#VRML_SIM R2021a utf8
WorldInfo {
  info [
    "generated from eus2webots"
  ]
  title "kxrl2w2l5a4h2 demo"
  basicTimeStep 1
  CFM  1.000000e-04   # default 0.00001
  ERP  0.2   # default 0.2
  defaultDamping Damping {
    linear 0.5
    angular 0.5
  }
  coordinateSystem "NUE" 
}
Viewpoint {
  fieldOfView 1.1
  position 0.9 1.5 2.0
  orientation  -0.780486 0.58667 0.216011 0.599585
}

TexturedBackground {
}
TexturedBackgroundLight {
}
Floor {
tileSize 1 1
}

# Solid {
#   name "ball138"
#   translation 1.74957 0.2 0.150468
#   recognitionColors [ 0 0.8 0 ]
#   model "ball"
#   children [
#     Shape {
#       appearance DEF DARK_BROWN PBRAppearance {
#         baseColor 0.1 0.9 0.1
#         roughness 0.01
#         metalness 0
#       }
#       geometry DEF BALL_GEOM Sphere {
#         radius 0.1
#         subdivision 3
#       }
#     }
#   ]
#   immersionProperties [
#     ImmersionProperties {
#       fluidName "fluid"
#       dragForceCoefficients 0.1 0 0
#       dragTorqueCoefficients 0.001 0 0
#       viscousResistanceTorqueCoefficient 0.005 } ]
#   boundingObject USE BALL_GEOM
#   physics Physics {
#     density 300
#     damping Damping {
#       linear 0.5
#       angular 0.5
#     }
#   }  
# }

# Can {
#   name "can138"
#   translation 0.127434 0.2 -1.7132
#   immersionProperties [
#     ImmersionProperties {
#       fluidName "fluid"
#       dragForceCoefficients 0.1 0 0
#       dragTorqueCoefficients 0.001 0 0
#       viscousResistanceTorqueCoefficient 0.005 } ]
#   physics Physics {
#     density 500
#     damping Damping {
#       linear 0.5
#       angular 0.5
#     }
#   }  
  
# }

# Apple {
#   name "apple138"
#   translation -1.59116 0.2 -1.26605
#   immersionProperties [
#     ImmersionProperties {
#       fluidName "fluid"
#       dragForceCoefficients 0.1 0 0
#       dragTorqueCoefficients 0.001 0 0
#       viscousResistanceTorqueCoefficient 0.005 } ]
#   physics Physics {
#     density 500
#     damping Damping {
#       linear 0.5
#       angular 0.5
#     }
#   }  
  
# }

# JamJar {
#   name "jamjar138"
#   translation 0.79378 0.2 -0.735189
#   immersionProperties [
#     ImmersionProperties {
#       fluidName "fluid"
#       dragForceCoefficients 0.1 0 0
#       dragTorqueCoefficients 0.001 0 0
#       viscousResistanceTorqueCoefficient 0.005 } ]
#   physics Physics {
#     density 500
#     damping Damping {
#       linear 0.5
#       angular 0.5
#     }
#   }  
  
# }

# BiscuitBox {
#   name "biscuitbox138"
#   translation -1.87505 0.2 0.733684
#   immersionProperties [
#     ImmersionProperties {
#       fluidName "fluid"
#       dragForceCoefficients 0.1 0 0
#       dragTorqueCoefficients 0.001 0 0
#       viscousResistanceTorqueCoefficient 0.005 } ]
#   physics Physics {
#     density 500
#     damping Damping {
#       linear 0.5
#       angular 0.5
#     }
#   }  
  
# }

# OilBarrel {
#   name "oilbarrel138"
#   translation 0.279224 0.2 -0.378484
#   immersionProperties [
#     ImmersionProperties {
#       fluidName "fluid"
#       dragForceCoefficients 0.1 0 0
#       dragTorqueCoefficients 0.001 0 0
#       viscousResistanceTorqueCoefficient 0.005 } ]
#   physics Physics {
#     density 500
#     damping Damping {
#       linear 0.5
#       angular 0.5
#     }
#   }  
#   radius 0.1 height 0.233333
# }

# Solid {
#   name "ball139"
#   translation 1.05682 0.2 -1.89063
#   recognitionColors [ 0 0.8 0 ]
#   model "ball"
#   children [
#     Shape {
#       appearance DEF DARK_BROWN PBRAppearance {
#         baseColor 0.1 0.9 0.1
#         roughness 0.01
#         metalness 0
#       }
#       geometry DEF BALL_GEOM Sphere {
#         radius 0.1
#         subdivision 3
#       }
#     }
#   ]
#   immersionProperties [
#     ImmersionProperties {
#       fluidName "fluid"
#       dragForceCoefficients 0.1 0 0
#       dragTorqueCoefficients 0.001 0 0
#       viscousResistanceTorqueCoefficient 0.005 } ]
#   boundingObject USE BALL_GEOM
#   physics Physics {
#     density 300
#     damping Damping {
#       linear 0.5
#       angular 0.5
#     }
#   }  
# }

# Can {
#   name "can139"
#   translation 0.164716 0.2 0.46374
#   immersionProperties [
#     ImmersionProperties {
#       fluidName "fluid"
#       dragForceCoefficients 0.1 0 0
#       dragTorqueCoefficients 0.001 0 0
#       viscousResistanceTorqueCoefficient 0.005 } ]
#   physics Physics {
#     density 500
#     damping Damping {
#       linear 0.5
#       angular 0.5
#     }
#   }  
  
# }

# Apple {
#   name "apple139"
#   translation 1.84893 0.2 -0.757148
#   immersionProperties [
#     ImmersionProperties {
#       fluidName "fluid"
#       dragForceCoefficients 0.1 0 0
#       dragTorqueCoefficients 0.001 0 0
#       viscousResistanceTorqueCoefficient 0.005 } ]
#   physics Physics {
#     density 500
#     damping Damping {
#       linear 0.5
#       angular 0.5
#     }
#   }  
  
# }

# JamJar {
#   name "jamjar139"
#   translation -0.097569 0.2 -1.4597
#   immersionProperties [
#     ImmersionProperties {
#       fluidName "fluid"
#       dragForceCoefficients 0.1 0 0
#       dragTorqueCoefficients 0.001 0 0
#       viscousResistanceTorqueCoefficient 0.005 } ]
#   physics Physics {
#     density 500
#     damping Damping {
#       linear 0.5
#       angular 0.5
#     }
#   }  
  
# }

# BiscuitBox {
#   name "biscuitbox139"
#   translation -1.32046 0.2 0.006882
#   immersionProperties [
#     ImmersionProperties {
#       fluidName "fluid"
#       dragForceCoefficients 0.1 0 0
#       dragTorqueCoefficients 0.001 0 0
#       viscousResistanceTorqueCoefficient 0.005 } ]
#   physics Physics {
#     density 500
#     damping Damping {
#       linear 0.5
#       angular 0.5
#     }
#   }  
  
# }

# OilBarrel {
#   name "oilbarrel139"
#   translation 0.623725 0.2 -0.848901
#   immersionProperties [
#     ImmersionProperties {
#       fluidName "fluid"
#       dragForceCoefficients 0.1 0 0
#       dragTorqueCoefficients 0.001 0 0
#       viscousResistanceTorqueCoefficient 0.005 } ]
#   physics Physics {
#     density 500
#     damping Damping {
#       linear 0.5
#       angular 0.5
#     }
#   }  
#   radius 0.1 height 0.233333
# }

# Solid {
#   name "ball140"
#   translation -1.25368 0.2 1.37464
#   recognitionColors [ 0 0.8 0 ]
#   model "ball"
#   children [
#     Shape {
#       appearance DEF DARK_BROWN PBRAppearance {
#         baseColor 0.1 0.9 0.1
#         roughness 0.01
#         metalness 0
#       }
#       geometry DEF BALL_GEOM Sphere {
#         radius 0.1
#         subdivision 3
#       }
#     }
#   ]
#   immersionProperties [
#     ImmersionProperties {
#       fluidName "fluid"
#       dragForceCoefficients 0.1 0 0
#       dragTorqueCoefficients 0.001 0 0
#       viscousResistanceTorqueCoefficient 0.005 } ]
#   boundingObject USE BALL_GEOM
#   physics Physics {
#     density 300
#     damping Damping {
#       linear 0.5
#       angular 0.5
#     }
#   }  
# }

# Can {
#   name "can140"
#   translation -1.8508 0.2 0.009302
#   immersionProperties [
#     ImmersionProperties {
#       fluidName "fluid"
#       dragForceCoefficients 0.1 0 0
#       dragTorqueCoefficients 0.001 0 0
#       viscousResistanceTorqueCoefficient 0.005 } ]
#   physics Physics {
#     density 500
#     damping Damping {
#       linear 0.5
#       angular 0.5
#     }
#   }  
  
# }

# Apple {
#   name "apple140"
#   translation 1.72828 0.2 -0.317983
#   immersionProperties [
#     ImmersionProperties {
#       fluidName "fluid"
#       dragForceCoefficients 0.1 0 0
#       dragTorqueCoefficients 0.001 0 0
#       viscousResistanceTorqueCoefficient 0.005 } ]
#   physics Physics {
#     density 500
#     damping Damping {
#       linear 0.5
#       angular 0.5
#     }
#   }  
  
# }

# JamJar {
#   name "jamjar140"
#   translation -0.028676 0.2 0.547844
#   immersionProperties [
#     ImmersionProperties {
#       fluidName "fluid"
#       dragForceCoefficients 0.1 0 0
#       dragTorqueCoefficients 0.001 0 0
#       viscousResistanceTorqueCoefficient 0.005 } ]
#   physics Physics {
#     density 500
#     damping Damping {
#       linear 0.5
#       angular 0.5
#     }
#   }  
  
# }

# BiscuitBox {
#   name "biscuitbox140"
#   translation -1.45169 0.2 -0.859243
#   immersionProperties [
#     ImmersionProperties {
#       fluidName "fluid"
#       dragForceCoefficients 0.1 0 0
#       dragTorqueCoefficients 0.001 0 0
#       viscousResistanceTorqueCoefficient 0.005 } ]
#   physics Physics {
#     density 500
#     damping Damping {
#       linear 0.5
#       angular 0.5
#     }
#   }  
  
# }

# OilBarrel {
#   name "oilbarrel140"
#   translation -1.91117 0.2 1.77897
#   immersionProperties [
#     ImmersionProperties {
#       fluidName "fluid"
#       dragForceCoefficients 0.1 0 0
#       dragTorqueCoefficients 0.001 0 0
#       viscousResistanceTorqueCoefficient 0.005 } ]
#   physics Physics {
#     density 500
#     damping Damping {
#       linear 0.5
#       angular 0.5
#     }
#   }  
#   radius 0.1 height 0.233333
# }

### from ~/webots/projects/samples/howto/worlds/pedal_racer.wbt
DEF PEDAL_RACER Solid {
  translation 0 0.075 0
  rotation 0.000000 1.000000 0.0 -1.57
  scale 0.7500 0.7500 0.7500
  children [
    DEF RIGHT_PEDAL_GROUP Group {
      children [
        DEF FRONT_CYLINDER Transform {
          translation 0.08 0.038 0.09
          children [
            DEF PEDAL_FRONT_HALF_CYLINDER Shape {
              appearance DEF RED_PLASTIC PBRAppearance {
                baseColor 0.8 0.094453 0.068437
                roughness 0.04174483200000001
                metalness 0
              }
              geometry Cylinder {
                height 0.0249
                radius 0.055
                subdivision 24
              }
            }
          ]
        }
        DEF MIDDLE_BOX Transform {
          translation 0.08 0.038 0
          children [
            Shape {
              appearance USE RED_PLASTIC
              geometry Box {
                size 0.11 0.025 0.2
              }
            }
          ]
        }
        DEF BACK_CYLINDER Transform {
          translation 0.08 0.038 -0.09
          children [
            DEF PEDAL_FRONT_HALF_CYLINDER Shape {
              appearance DEF RED_PLASTIC PBRAppearance {
                baseColor 0.8 0.094453 0.068437
                roughness 0.04174483200000001
                metalness 0
              }
              geometry Cylinder {
                height 0.0249
                radius 0.055
                subdivision 24
              }
            }
          ]
        }
      ]
    }
    DEF PLASTIC_HINGES Group {
      children [
        DEF BACK_HINGE Transform {
          translation 0.144 0.038 0.11
          rotation 0 0 1 1.5708
          children [
            Shape {
              appearance USE RED_PLASTIC
              geometry Cylinder {
                height 0.036
                radius 0.013
                subdivision 24
              }
            }
          ]
        }
        DEF FRONT_HINGE Transform {
          translation 0.144 0.038 -0.11
          rotation 0 0 1 1.5708
          children [
            Shape {
              appearance USE RED_PLASTIC
              geometry Cylinder {
                height 0.036
                radius 0.013
                subdivision 24
              }
            }
          ]
        }
      ]
    }
    DEF BACK_RIGHT_AXLE_HINGE HingeJoint {
      jointParameters HingeJointParameters {
        anchor 0.08 0.038 0.11
      }
      endPoint DEF BACK_AXLE Solid {
        rotation 1 0 0 0
        children [
          DEF BACK_RIGHT_WHEEL Solid {
            rotation 1 0 0 0
            children [
              Group {
                children [
                  DEF BLACK_TIRE Transform {
                    translation 0.2125 0 0.11
                    rotation 0 0 1 1.5708
                    children [
                      Shape {
                        appearance PBRAppearance {
                          baseColor 0.036484 0.036484 0.036484
                          roughness 0.2772110000000001
                          metalness 0
                        }
                        geometry Cylinder {
                          height 0.025
                          radius 0.075
                          subdivision 24
                        }
                      }
                    ]
                  }
                  DEF RED_RIM Transform {
                    translation 0.2125 0 0.11
                    rotation 0 0 1 1.5708
                    children [
                      Shape {
                        appearance USE RED_PLASTIC
                        geometry Cylinder {
                          height 0.0255
                          radius 0.058
                          subdivision 24
                        }
                      }
                    ]
                  }
                  DEF ANCHOR Transform {
                    translation 0.19 0.038 0.11
                    rotation 0 0 1 1.5708
                    children [
                      Shape {
                        appearance USE RED_PLASTIC
                        geometry Cylinder {
                          height 0.025
                          radius 0.013
                          subdivision 24
                        }
                      }
                    ]
                  }
                ]
              }
            ]
            name "back right wheel"
            boundingObject USE BLACK_TIRE
            physics DEF PLASTIC_DENSITY Physics {
              density 750
            }
          }
          DEF BACK_LEFT_WHEEL Solid {
            rotation 1 0 0 0
            children [
              Group {
                children [
                  DEF BLACK_TIRE Transform {
                    translation -0.2125 0 0.11
                    rotation 0 0 1 1.5708
                    children [
                      Shape {
                        appearance PBRAppearance {
                          baseColor 0.036484 0.036484 0.036484
                          roughness 0.2772110000000001
                          metalness 0
                        }
                        geometry Cylinder {
                          height 0.025
                          radius 0.075
                          subdivision 24
                        }
                      }
                    ]
                  }
                  DEF RED_RIM Transform {
                    translation -0.2125 0 0.11
                    rotation 0 0 1 1.5708
                    children [
                      Shape {
                        appearance USE RED_PLASTIC
                        geometry Cylinder {
                          height 0.0255
                          radius 0.058
                          subdivision 24
                        }
                      }
                    ]
                  }
                  DEF ANCHOR Transform {
                    translation -0.19 -0.038 0.11
                    rotation 0 0 1 1.5708
                    children [
                      Shape {
                        appearance USE RED_PLASTIC
                        geometry Cylinder {
                          height 0.025
                          radius 0.013
                          subdivision 24
                        }
                      }
                    ]
                  }
                ]
              }
            ]
            name "back left wheel"
            boundingObject USE BLACK_TIRE
            physics USE PLASTIC_DENSITY
          }
          DEF LEFT_PEDAL_HINGE HingeJoint {
            jointParameters HingeJointParameters {
              anchor -0.08 -0.038 0.11
            }
            endPoint DEF LEFT_PEDAL Solid {
              rotation 1 0 0 0
              children [
                DEF LEFT_PEDAL_GROUP Group {
                  children [
                    DEF FRONT_CYLINDER Transform {
                      translation -0.08 -0.038 0.09
                      children [
                        DEF PEDAL_FRONT_HALF_CYLINDER Shape {
                          appearance DEF RED_PLASTIC PBRAppearance {
                            baseColor 0.8 0.094453 0.068437
                            roughness 0.04174483200000001
                            metalness 0
                          }
                          geometry Cylinder {
                            height 0.0249
                            radius 0.055
                            subdivision 24
                          }
                        }
                      ]
                    }
                    DEF MIDDLE_BOX Transform {
                      translation -0.08 -0.038 0
                      children [
                        Shape {
                          appearance USE RED_PLASTIC
                          geometry Box {
                            size 0.11 0.025 0.2
                          }
                        }
                      ]
                    }
                    DEF BACK_CYLINDER Transform {
                      translation -0.08 -0.038 -0.09
                      children [
                        DEF PEDAL_FRONT_HALF_CYLINDER Shape {
                          appearance DEF RED_PLASTIC PBRAppearance {
                            baseColor 0.8 0.094453 0.068437
                            roughness 0.04174483200000001
                            metalness 0
                          }
                          geometry Cylinder {
                            height 0.0249
                            radius 0.055
                            subdivision 24
                          }
                        }
                      ]
                    }
                  ]
                }
                DEF PLASTIC_HINGES Group {
                  children [
                    DEF BACK_HINGE Transform {
                      translation -0.144 -0.038 0.11
                      rotation 0 0 1 1.5708
                      children [
                        Shape {
                          appearance USE RED_PLASTIC
                          geometry Cylinder {
                            height 0.036
                            radius 0.013
                            subdivision 24
                          }
                        }
                      ]
                    }
                    DEF FRONT_HINGE Transform {
                      translation -0.144 -0.038 -0.11
                      rotation 0 0 1 1.5708
                      children [
                        Shape {
                          appearance USE RED_PLASTIC
                          geometry Cylinder {
                            height 0.036
                            radius 0.013
                            subdivision 24
                          }
                        }
                      ]
                    }
                  ]
                }
                DEF FRONT_AXLE_HINGE HingeJoint {
                  jointParameters HingeJointParameters {
                    anchor -0.08 -0.038 -0.11
                  }
                  endPoint SolidReference {
                    solidName "front axle"
                  }
                }
              ]
              name "left pedal"
              boundingObject USE LEFT_PEDAL_GROUP
              physics USE PLASTIC_DENSITY
            }
          }
          DEF AXLE_GROUP Group {
            children [
              DEF MIDDLE_SEGMENT Transform {
                translation 0 0 0.11
                rotation 0 0 1 -0.5
                children [
                  DEF SMALL_CAPSULE Shape {
                    appearance DEF METAL PBRAppearance {
                      baseColor 0.556786 0.618021 0.668055
                      roughness 0.10093799999999997
                      metalness 0
                    }
                    geometry DEF SMALL_CAPSULE_SEGMENT Capsule {
                      height 0.07
                      radius 0.007
                    }
                  }
                ]
              }
              DEF UPPER_SEGMENT Transform {
                translation 0.105 0.038 0.11
                rotation 0 0 1 1.5708
                children [
                  DEF LONG_CAPSULE Shape {
                    appearance DEF METAL PBRAppearance {
                      baseColor 0.556786 0.618021 0.668055
                      roughness 0.10093799999999997
                      metalness 0
                    }
                    geometry Capsule {
                      height 0.17
                      radius 0.007
                    }
                  }
                ]
              }
              DEF LOWER_SEGMENT Transform {
                translation -0.105 -0.038 0.11
                rotation 0 0 1 1.5708
                children [
                  USE LONG_CAPSULE
                ]
              }
            ]
          }
        ]
        name "back axle"
        boundingObject USE AXLE_GROUP
        physics DEF METAL_DENSITY Physics {
          density 2500
        }
      }
    }
    DEF FRONT_RIGHT_AXLE_HINGE HingeJoint {
      jointParameters HingeJointParameters {
        anchor 0.08 0.038 -0.11
      }
      endPoint DEF FRONT_AXLE Solid {
        rotation 1 0 0 0
        children [
          DEF FRONT_RIGHT_WHEEL Solid {
            rotation 1 0 0 0
            children [
              Group {
                children [
                  DEF BLACK_TIRE Transform {
                    translation 0.2125 0 -0.11
                    rotation 0 0 1 1.5708
                    children [
                      Shape {
                        appearance PBRAppearance {
                          baseColor 0.036484 0.036484 0.036484
                          roughness 0.2772110000000001
                          metalness 0
                        }
                        geometry Cylinder {
                          height 0.025
                          radius 0.075
                          subdivision 24
                        }
                      }
                    ]
                  }
                  DEF RED_RIM Transform {
                    translation 0.2125 0 -0.11
                    rotation 0 0 1 1.5708
                    children [
                      Shape {
                        appearance USE RED_PLASTIC
                        geometry Cylinder {
                          height 0.0255
                          radius 0.058
                          subdivision 24
                        }
                      }
                    ]
                  }
                  DEF ANCHOR Transform {
                    translation 0.19 0.038 -0.11
                    rotation 0 0 1 1.5708
                    children [
                      Shape {
                        appearance USE RED_PLASTIC
                        geometry Cylinder {
                          height 0.025
                          radius 0.013
                          subdivision 24
                        }
                      }
                    ]
                  }
                ]
              }
            ]
            name "front right wheel"
            boundingObject USE BLACK_TIRE
            physics USE PLASTIC_DENSITY
          }
          DEF FRONT_LEFT_WHEEL Solid {
            rotation 1 0 0 0
            children [
              Group {
                children [
                  DEF BLACK_TIRE Transform {
                    translation -0.2125 0 -0.11
                    rotation 0 0 1 1.5708
                    children [
                      Shape {
                        appearance PBRAppearance {
                          baseColor 0.036484 0.036484 0.036484
                          roughness 0.2772110000000001
                          metalness 0
                        }
                        geometry Cylinder {
                          height 0.025
                          radius 0.075
                          subdivision 24
                        }
                      }
                    ]
                  }
                  DEF RED_RIM Transform {
                    translation -0.2125 0 -0.11
                    rotation 0 0 1 1.5708
                    children [
                      Shape {
                        appearance USE RED_PLASTIC
                        geometry Cylinder {
                          height 0.0255
                          radius 0.058
                          subdivision 24
                        }
                      }
                    ]
                  }
                  DEF ANCHOR Transform {
                    translation -0.19 -0.038 -0.11
                    rotation 0 0 1 1.5708
                    children [
                      Shape {
                        appearance USE RED_PLASTIC
                        geometry Cylinder {
                          height 0.025
                          radius 0.013
                          subdivision 24
                        }
                      }
                    ]
                  }
                ]
              }
            ]
            name "front left wheel"
            boundingObject USE BLACK_TIRE
            physics USE PLASTIC_DENSITY
          }
          DEF AXLE_GROUP Group {
            children [
              DEF MIDDLE_SEGMENT Transform {
                translation 0 0 -0.11
                rotation 0 0 1 -0.5
                children [
                  USE SMALL_CAPSULE
                ]
              }
              DEF UPPER_SEGMENT Transform {
                translation 0.105 0.038 -0.11
                rotation 0 0 1 1.5708
                children [
                  USE LONG_CAPSULE
                ]
              }
              DEF LOWER_SEGMENT Transform {
                translation -0.105 -0.038 -0.11
                rotation 0 0 1 1.5708
                children [
                  USE LONG_CAPSULE
                ]
              }
            ]
          }
        ]
        name "front axle"
        boundingObject USE AXLE_GROUP
        physics USE METAL_DENSITY
      }
    }
  ]
  name "robot"
  boundingObject USE RIGHT_PEDAL_GROUP
  physics USE PLASTIC_DENSITY
}

kxrl2w2l5a4h2 {
  # translation 0.0 0.204288 0.0
  # translation 0.0 0.704288 0.0
  translation -0.6 0.704288 0.0
  rotation 1.000000 0.000000 0.0 -1.57 
  immersionProperties [ 
                  ImmersionProperties {
                  fluidName "fluid"
                  dragForceCoefficients 0.1 0 0
                  dragTorqueCoefficients 0.001 0 0
                  viscousResistanceTorqueCoefficient 0.005
                  }
                ]
  controller "<extern>"
  controllerArgs ""
  synchronization FALSE
}
